Workbook
Name Beta_e: WACC!$D$9
Name D: WACC!$D$14
Name E: WACC!$D$13
Name Equity_ratio: WACC!$D$15
Name Leverage: WACC!$D$16
Name MRP: WACC!$D$11
Name Rd: WACC!$D$18
Name Re: WACC!$D$8
Name Rf: WACC!$D$10
Name scenario: 'DCF model'!$C$18
Name Tax_shield: WACC!$D$19

Sheet Legend
B2: Legend
B4: XX | C4: Hardcoded
B5: XX | C5: Calculated formula in same sheet / same section
B6: XX | C6: Calculated formula, referencing other sheet
B7: XX | C7: Calculated formula, referencing different section of the sheet
B8: XX | C8: Assumption
B9: XX | C9: Number worth noting

Sheet Comp analysis
B2: Multiples analysis
A4: X | B4: Summary table
B6: Multiple used | C6: Low | D6: Max | E6: Diff
B7: DCF
B8: EV / Revenue - current
B9: EV / EBITDA - current
B10: Price / Revenue - current
B11: EV / Revenue - comp
B12: EV / EBITDA - comp
B13: Price / Revenue - comp
A15: X | B15: Input
B17: Stock price - 2024 | C17: ='DCF model'!C11 -> 98.87
B18: Revenue - 2024 | C18: ='DCF model'!O58 -> 36176.2
B19: Revenue - 2030 | C19: ='DCF model'!U58 -> 50491.977
B20: EBITDA - 2024 | C20: ='DCF model'!O64 -> 7935.1
B21: EBITDA - 2030 | C21: ='DCF model'!U64 -> 10098.395
B22: EV - 2030 | C22: ='DCF model'!U109 -> 57341.828
B23: Cash | C23: ='DCF model'!U110 -> 3543.2
B24: Debt | C24: ='DCF model'!U111 -> -15595.5
B25: Shares out | C25: ='DCF model'!U113 -> 1137
A27: X | B27: Using past data of Starbucks
A29: X | B29: EV / Revenue eval
B31: Multiple calculation
B32: EV - 2030 | C32: =C22 -> 57341.828
B33: Revenue - 2030 | C33: =C19 -> 50491.977
B34: EV/Revenue - post evaluation | C34: =C32/C33 -> 1.1356622
B36: Current evaluation - Pitchbook | C36: 3.66
B37: Current EV | C37: =C36*C18 -> 132404.89
B38: Current Revenues | C38: =C18 -> 36176.2
B40: Evaluation if we use 3.66x instead of 2.63x
B41: EV | C41: =C36*C33 -> 184800.64
B42: Plus: Cash | C42: =C23 -> 3543.2
B43: Less: Debt | C43: =C24 -> -15595.5
B44: Equity value | C44: =SUM(C41:C43) -> 172748.34
B45: Divided: Shares out | C45: =C25 -> 1137
B46: New price per share | C46: =C44/C45 -> 151.93345
A48: X | B48: EV / EBITDA eval
B50: Multiple calculation
B51: Current EV | C51: =C37 -> 132404.89
B52: EBITDA | C52: =C20 -> 7935.1
...

Sheet WACC
B2: WACC calculation
B3: all values in M
A4: X | B4: Inputs
B6: WACC = Re*(E/D+E)*Rd*(1-Tax)*(D/D+E)
B8: Re | D8: =Rf+Beta_e*MRP -> 0.08934
B9: Beta Equity | D9: 0.99
B10: Risk free rate | D10: 0.0438
B11: MRP | D11: 0.046
B13: E | D13: 112882
B14: D | D14: ='BS Estimates'!G9 -> 15595.5
B15: E/D+E | D15: =E/(D+E) -> 0.87861299
B16: D/D+E | D16: =D/(D+E) -> 0.12138701
B18: Rd | D18: =IS!L24 -> 0.024338381
B19: 1-Tax | D19: =1-'DCF model'!P77 -> 0.78100205
B21: WACC | D21: =Re*Equity_ratio+Rd*Tax_shield*Leverage -> 0.080802648

Sheet DCF model
F1: 2015 | G1: =+F1+1 -> 2016 | H1: =+G1+1 -> 2017 | I1: =+H1+1 -> 2018 | J1: =+I1+1 -> 2019 | K1: =+J1+1 -> 2020 | L1: =+K1+1 -> 2021 | M1: =+L1+1 -> 2022 | N1: =+M1+1 -> 2023 | ... U1: =+T1+1 -> 2030
B2: Starbucks DCF model
A4: X | B4: Overview
B6: Company name | C6: =CFS!A5 -> Starbucks Corporation
B7: Company Ticker | C7: SBUX
B8: Date | C8: 45599
B9: End of fiscal year | C9: 45930
B10: Year fraction to discount | C10: =YEARFRAC(C8,C9) -> 0.90833333
B11: Price per share - actual | C11: 98.87
B12: Price per share - post eval | C12: =U114 -> 39.832479
B13: Delta | C13: =C12/C11-1 -> -0.5971227
A15: X | B15: Assumptions
B17: Triggers | F17: 1 - Downside case | J17: 2 - Street case | N17: 3 - Upside case
B18: Scenario | C18: 1 | F18: WACC | H18: =WACC!D21 -> 0.080802648 | J18: WACC | K18: 0.0792 | N18: WACC | P18: 0.075
B19: WACC | C19: =CHOOSE(scenario,H18,K18,P18) -> 0.080802648 | F19: TGR | H19: 0.026 | J19: TGR | K19: 0.028 | N19: TGR | P19: 0.03
B20: TGR | C20: =CHOOSE(scenario,H19,K19,P19) -> 0.026 | F20: Rev g FY2025 % of base | H20: 0.9 | N20: Rev g FY2025 % of base | P20: 1.1
F21: Rev g FY2030 % of base | H21: 0.95 | N21: Rev g FY2030 % of base | P21: 1.05
F22: EBITDA % FY2025 | H22: 0.18 | N22: EBITDA g FY2025 | P22: 0.22
F23: EBITDA % FY2030 | H23: 0.2 | N23: EBITDA g FY2030 | P23: 0.26
F24: EBIT % FY2025 | H24: 0.13 | N24: EBIT % FY2025 | P24: 0.16
F25: EBIT % FY2030 | H25: 0.13 | N25: EBIT % FY2030 | P25: 0.19
F26: Capex % sales | H26: 0.08 | N26: Capex % sales | P26: 0.06
A30: X | B30: Financials
B32: Revenue | F32: =IS!B10 -> 19148.7 | G32: =IS!C10 -> 21311 | H32: =IS!D10 -> 22383.8 | I32: =IS!E10 -> 24719.9 | J32: =IS!F10 -> 26501.6 | K32: =IS!G10 -> 23512.5 | L32: =IS!H10 -> 29058.8 | M32: =IS!I10 -> 32228.3 | ... O32: =IS!K10 -> 36176.2 | P32: ='IS Estimates'!G4 -> 37609.8 | Q32: ='IS Estimates'!H4 -> 40111.4 | R32: ='IS Estimates'!I4 -> 43529.3 | S32: ='IS Estimates'!J4 -> 46596.6 | T32: ='IS Estimates'!K4 -> 50804.9 | U32: ='IS Estimates'!L4 -> 55020.3
B33: % growth | G33: =G32/F32-1 -> 0.1129215 | H33: =H32/G32-1 -> 0.0503402 | I33: =I32/H32-1 -> 0.10436566 | J33: =J32/I32-1 -> 0.072075534 | K33: =K32/J32-1 -> -0.11278942 | L33: =L32/K32-1 -> 0.23588729 | M33: =M32/L32-1 -> 0.10907195 | N33: =N32/M32-1 -> 0.11554131 | ... U33: =U32/T32-1 -> 0.082972312
B35: EBITDA | F35: =IS!B59 -> 4300.6 | G35: =IS!C59 -> 4939.5 | H35: =IS!D59 -> 5018.3 | I35: =IS!E59 -> 5165.6 | J35: =IS!F59 -> 5353.9 | K35: =IS!G59 -> 4217.4 | L35: =IS!H59 -> 7437.2 | M35: =IS!I59 -> 7304.4 | ... O35: =IS!K59 -> 7935.1 | P35: ='IS Estimates'!G13 -> 6998.44 | Q35: ='IS Estimates'!H13 -> 7803.61 | R35: ='IS Estimates'!I13 -> 8862.69 | S35: ='IS Estimates'!J13 -> 9810.3 | T35: ='IS Estimates'!K13 -> 10945.9 | U35: ='IS Estimates'!L13 -> 12196.9
B36: % sales | F36: =F35/F$32 -> 0.22458966 | G36: =G35/G32 -> 0.23178171 | H36: =H35/H32 -> 0.22419339 | I36: =I35/I32 -> 0.20896525 | J36: =J35/J32 -> 0.20202176 | K36: =K35/K32 -> 0.17936842 | L36: =L35/L32 -> 0.25593624 | M36: =M35/M32 -> 0.22664553 | N36: =N35/N32 -> 0.1898281 | ... U36: =U35/U32 -> 0.22168
B38: EBIT | F38: =IS!B60 -> 3366.8 | G38: =IS!C60 -> 3909.4 | H38: =IS!D60 -> 3951.2 | I38: =IS!E60 -> 3859.7 | J38: =IS!F60 -> 3904.6 | K38: =IS!G60 -> 1516.6 | L38: =IS!H60 -> 4664.5 | M38: =IS!I60 -> 4277.3 | ... O38: =IS!K60 -> 5107.6 | P38: ='IS Estimates'!G17 -> 5362.79 | Q38: ='IS Estimates'!H17 -> 6213.02 | R38: ='IS Estimates'!I17 -> 7123.84 | S38: ='IS Estimates'!J17 -> 8482.45 | T38: ='IS Estimates'!K17 -> 8760.5 | U38: ='IS Estimates'!L17 -> 9833.4
B39: % sales | F39: =F38/F$32 -> 0.17582395 | G39: =G38/G$32 -> 0.18344517 | H39: =H38/H$32 -> 0.17652052 | I39: =I38/I$32 -> 0.15613736 | J39: =J38/J$32 -> 0.1473345 | K39: =K38/K$32 -> 0.064501861 | L39: =L38/L$32 -> 0.16051936 | M39: =M38/M$32 -> 0.13271876 | ... U39: =U38/U$32 -> 0.17872313
B41: Taxes | F41: =IS!B38 -> 1143.7 | G41: =IS!C38 -> 1379.7 | H41: =IS!D38 -> 1432.6 | I41: =IS!E38 -> 1262 | J41: =IS!F38 -> 871.6 | K41: =IS!G38 -> 239.7 | L41: =IS!H38 -> 1156.6 | M41: =IS!I38 -> 948.5 | ... O41: =IS!K38 -> 1207.3 | P41: ='IS Estimates'!G32 -> 1174.44 | Q41: ='IS Estimates'!H32 -> 1362.31 | R41: ='IS Estimates'!I32 -> 1599.05 | S41: ='IS Estimates'!J32 -> 1934.05 | T41: ='IS Estimates'!K32 -> 2020.4 | U41: ='IS Estimates'!L32 -> 2283.2
B42: % tax rate | F42: =F41/F38 -> 0.33969942 | G42: =G41/G38 -> 0.35291861 | H42: =H41/H38 -> 0.3625734 | I42: =I41/I38 -> 0.32696842 | J42: =J41/J38 -> 0.22322389 | K42: =K41/K38 -> 0.1580509 | L42: =L41/L38 -> 0.24795798 | M42: =M41/M38 -> 0.22175204 | ... U42: =U41/U38 -> 0.23218826
A44: X | B44: Cash flow items
B46: D&A | F46: =IS!B61 -> 933.8 | G46: =IS!C61 -> 1030.1 | H46: =IS!D61 -> 1067.1 | I46: =IS!E61 -> 1305.9 | J46: =IS!F61 -> 1449.3 | K46: =IS!G61 -> 2700.8 | L46: =IS!H61 -> 2772.7 | M46: =IS!I61 -> 3027.1 | ... O46: =IS!K61 -> 2827.5 | P46: ='IS Estimates'!G16 -> 1620.4 | Q46: ='IS Estimates'!H16 -> 1715.81 | R46: ='IS Estimates'!I16 -> 1826.62 | S46: ='IS Estimates'!J16 -> 2032.25 | T46: ='IS Estimates'!K16 -> 2185.5 | U46: ='IS Estimates'!L16 -> 2363.5
B47: % sales | F47: =F46/F32 -> 0.048765713 | G47: =G46/G32 -> 0.04833654 | H47: =H46/H32 -> 0.047672871 | I47: =I46/I32 -> 0.052827884 | J47: =J46/J32 -> 0.054687264 | K47: =K46/K32 -> 0.11486656 | L47: =L46/L32 -> 0.095416879 | M47: =M46/M32 -> 0.093926766 | ... U47: =U46/U32 -> 0.042956872
B48: % capex
B50: Capex | F50: =CFS!B27 -> -1303.7 | G50: =CFS!C27 -> -1440.3 | H50: =CFS!D27 -> -1519.4 | I50: =CFS!E27 -> -1976.4 | J50: =CFS!F27 -> -1806.6 | K50: =CFS!G27 -> -1483.6 | L50: =CFS!H27 -> -1470 | M50: =CFS!I27 -> -1841.3 | ... O50: =CFS!K27 -> -2777.5 | P50: =-'CFS Estimates'!G4 -> -2707.57 | Q50: =-'CFS Estimates'!H4 -> -2978.22 | R50: =-'CFS Estimates'!I4 -> -3359.48 | S50: =-'CFS Estimates'!J4 -> -3833 | T50: =T32*T51 -> -3957.4541 | U50: =U32*U51 -> -4352.6887
B51: % sales | F51: =F50/F$32 -> -0.068082951 | G51: =G50/G$32 -> -0.067584815 | H51: =H50/H$32 -> -0.067879449 | I51: =I50/I$32 -> -0.07995178 | J51: =J50/J$32 -> -0.068169469 | K51: =K50/K$32 -> -0.063098352 | L51: =L50/L$32 -> -0.050587085 | M51: =M50/M$32 -> -0.057133017 | ... S51: =S50/S$32 -> -0.082259221 | T51: =AVERAGE(Q51:S51) -> -0.077895126 | U51: =AVERAGE(R51:T51) -> -0.079110596
B53: Change in WC | F53: =CFS!B19 -> 278.8 | G53: =CFS!C19 -> 353 | H53: =CFS!D19 -> 89.7 | I53: =CFS!E19 -> 6913.7 | J53: =CFS!F19 -> 1648.7 | K53: =CFS!G19 -> -2676.4 | L53: =CFS!H19 -> -501.2 | M53: =CFS!I19 -> -2133 | ... O53: =CFS!K19 -> 246.1 | P53: =P32*P54 -> -1016.9164 | Q53: =Q32*Q54 -> -1182.737 | R53: =R32*R54 -> -884.16126 | S53: =S32*S54 -> -815.83607 | T53: =T32*T54 -> -1198.3004 | U53: =U32*U54 -> -1250.2397
B54: % sales | F54: =F53/F$32 -> 0.014559735 | G54: =G53/G$32 -> 0.016564216 | H54: =H53/H$32 -> 0.0040073625 | I54: =I53/I$32 -> 0.27968155 | J54: =J53/J$32 -> 0.062211338 | K54: =K53/K$32 -> -0.11382881 | L54: =L53/L$32 -> -0.017247787 | M54: =M53/M$32 -> -0.066184068 | ... O54: =O53/O$32 -> 0.0068028151 | P54: =AVERAGE(L54:O54) -> -0.027038602 | Q54: =AVERAGE(M54:P54) -> -0.029486305 | R54: =AVERAGE(N54:Q54) -> -0.020311865 | S54: =AVERAGE(O54:R54) -> -0.017508489 | T54: =AVERAGE(P54:S54) -> -0.023586315 | U54: =AVERAGE(Q54:T54) -> -0.022723244
A56: X | B56: DCF model
...

Sheet RAW DATA >>

Sheet CFS
A1: Starbucks Corporation (SBUX)
A2: $99.04
A5: Starbucks Corporation
A6: SBUX 855244109 2842255 NASDAQ Common stock
A7: Source: FactSet Fundamentals
B8: SEP '15 | C8: SEP '16 | D8: SEP '17 | E8: SEP '18 | F8: SEP '19 | G8: SEP '20 | H8: SEP '21 | I8: SEP '22 | J8: SEP '23 | K8: SEP '24
B9: Restate | C9: Restate | K9: Preliminary
A10: Operating Activities
A11: Net Income / Starting Line | B11: 2759.3 | C11: 2818.9 | D11: 2884.9 | E11: 4518 | F11: 3594.6 | G11: 924.7 | H11: 4200.3 | I11: 3283.4 | J11: 4124.7 | K11: 3762.3
A12: Depreciation, Depletion & Amortization | B12: 933.8 | C12: 1030.1 | D12: 1067.1 | E12: 1305.9 | F12: 1449.3 | G12: 2700.8 | H12: 2772.7 | I12: 3027.1 | J12: 1450.3 | K12: 2907.3
A13: Depreciation and Depletion | B13: 883.8 | C13: 972.8 | D13: 1009.6 | E13: 1119.4 | F13: 1216.5 | G13: 2477.1 | H13: 2549.3 | I13: 2834.4 | J13: 1428.8
A14: Amortization of Intangible Assets | B14: 50 | C14: 57.3 | D14: 57.5 | E14: 186.5 | F14: 232.8 | G14: 223.7 | H14: 223.4 | I14: 192.7 | J14: 21.5
A15: Deferred Taxes & Investment Tax Credit | B15: 21.2 | C15: 265.7 | D15: 95.1 | E15: 714.9 | F15: -1495.4 | G15: -25.8 | H15: -146.2 | I15: -37.8 | J15: -59.4 | K15: -13.8
A16: Deferred Taxes | B16: 21.2 | C16: 265.7 | D16: 95.1 | E16: 714.9 | F16: -1495.4 | G16: -25.8 | H16: -146.2 | I16: -37.8 | J16: -59.4 | K16: -13.8
A17: Other Funds | B17: -244 | C17: 107.4 | D17: 37.5 | E17: -1514.7 | F17: -150.2 | G17: 674.5 | H17: -336.5 | I17: 257.6 | J17: 1626.5 | K17: 488.6
A18: Funds from Operations | B18: 3470.3 | C18: 4222.1 | D18: 4084.6 | E18: 5024.1 | F18: 3398.3 | G18: 4274.2 | H18: 6490.3 | I18: 6530.3 | J18: 7142.1 | K18: 7144.4
A19: Changes in Working Capital | B19: 278.8 | C19: 353 | D19: 89.7 | E19: 6913.7 | F19: 1648.7 | G19: -2676.4 | H19: -501.2 | I19: -2133 | J19: -1133.4 | K19: 246.1
A20: Receivables | B20: -82.8 | C20: -55.6 | D20: -96.8 | E20: 131 | F20: -197.7 | G20: -2.7 | H20: -43 | I20: -326.1 | J20: -4.1 | K20: 18.4
A21: Inventories | B21: -207.9 | C21: -67.5 | D21: 14 | E21: -41.2 | F21: -173 | G21: -10.9 | H21: -49.8 | I21: -641 | J21: 366.4 | K21: 42.8
A22: Accounts Payable | B22: 137.7 | C22: 46.9 | D22: 46.4 | E22: 391.6 | F22: 31.9 | G22: -210.8 | H22: 189.9 | I22: 345.5 | J22: 100.1 | K22: 28
A23: Income Taxes Payable | F23: 1237.1 | G23: -1214.6 | H23: 286.1 | I23: -149.6 | J23: 52.5 | K23: -61.9
A24: Other Assets/Liabilities | B24: 431.8 | C24: 429.2 | D24: 126.1 | E24: 6432.3 | F24: 750.4 | G24: -1237.4 | H24: -884.4 | I24: -1361.8 | J24: -1648.3 | K24: -1658.1
A25: Net Operating Cash Flow | B25: 3749.1 | C25: 4575.1 | D25: 4174.3 | E25: 11937.8 | F25: 5047 | G25: 1597.8 | H25: 5989.1 | I25: 4397.3 | J25: 6008.7 | K25: 7390.5
A26: Investing Activities
A27: Capital Expenditures | B27: -1303.7 | C27: -1440.3 | D27: -1519.4 | E27: -1976.4 | F27: -1806.6 | G27: -1483.6 | H27: -1470 | I27: -1841.3 | J27: -2333.6 | K27: -2777.5
A28: Capital Expenditures (Fixed Assets) | B28: -1303.7 | C28: -1440.3 | D28: -1519.4 | E28: -1976.4 | F28: -1806.6 | G28: -1483.6 | H28: -1470 | I28: -1841.3 | J28: -2333.6 | K28: -2777.5
A29: Net Assets from Acquisitions | B29: -645.1 | C29: 0 | D29: 0 | E29: -1311.3 | F29: 0 | G29: 0 | H29: 0 | I29: 0 | J29: 0
A30: Sale of Fixed Assets & Businesses | C30: 0 | D30: 0 | E30: 608.2 | F30: 684.3 | G30: 0 | H30: 1175 | I30: 59.3 | J30: 0 | K30: 0
A31: Purchase/Sale of Investments | B31: 60.9 | C31: -807.5 | D31: 615.1 | E31: 312.4 | F31: 167.7 | G31: -183.5 | H31: 56.7 | I31: -238 | J31: 8.9 | K31: 151
A32: Purchase of Investments | B32: 567.4 | C32: 1585.7 | D32: 674.4 | E32: 191.9 | F32: 190.4 | G32: 443.9 | H32: 432 | I32: 377.9 | J32: 610.5 | K32: 627.5
A33: Sale/Maturity of Investments | B33: 628.3 | C33: 778.2 | D33: 1289.5 | E33: 504.3 | F33: 358.1 | G33: 260.4 | H33: 488.7 | I33: 139.9 | J33: 619.4 | K33: 778.5
A34: Other Funds | B34: 6.8 | C34: 24.9 | D34: 54.3 | E34: 5.6 | F34: -56.2 | G34: -44.4 | H34: -81.2 | I34: -126.3 | J34: 53.9 | K34: -72.7
A35: Other Uses | B35: 0 | C35: 0 | D35: 0 | E35: 0 | F35: -56.2 | G35: -44.4 | H35: -81.2 | I35: -126.3 | J35: -56.1 | K35: -72.7
A36: Other Sources | B36: 6.8 | C36: 24.9 | D36: 54.3 | E36: 5.6 | F36: 0 | G36: 0 | H36: 0 | I36: 0 | J36: 110
A37: Net Investing Cash Flow | B37: -1881.1 | C37: -2222.9 | D37: -850 | E37: -2361.5 | F37: -1010.8 | G37: -1711.5 | H37: -319.5 | I37: -2146.3 | J37: -2270.8 | K37: -2699.2
A38: Financing Activities
A39: Cash Dividends Paid | B39: -928.6 | C39: -1178 | D39: -1450.4 | E39: -1743.4 | F39: -1761.3 | G39: -1923.5 | H39: -2119 | I39: -2263.3 | J39: -2431.8 | K39: -2585
A40: Common Dividends | B40: -928.6 | C40: -1178 | D40: -1450.4 | E40: -1743.4 | F40: -1761.3 | G40: -1923.5 | H40: -2119 | I40: -2263.3 | J40: -2431.8 | K40: -2585
A41: Change in Capital Stock | B41: -1244.3 | C41: -1834.9 | D41: -1891.7 | E41: -6979.6 | F41: -9812.5 | G41: -1400.1 | H41: 246.2 | I41: -3911.4 | J41: -817 | K41: -1158.7
A42: Repurchase of Common & Preferred Stk. | B42: -1436.1 | C42: -1995.6 | D42: -2042.5 | E42: -7133.5 | F42: -10222.3 | G42: -1698.9 | H42: 0 | I42: -4013 | J42: -984.4 | K42: -1266.7
...

Sheet BS
A1: Starbucks Corporation (SBUX)
A2: $99.03
A4: Starbucks Corporation
A5: SBUX 855244109 2842255 NASDAQ Common stock
A6: Source: FactSet Fundamentals
B7: SEP '15 | C7: SEP '16 | D7: SEP '17 | E7: SEP '18 | F7: SEP '19 | G7: SEP '20 | H7: SEP '21 | I7: SEP '22 | J7: SEP '23 | K7: SEP '24
B8: Restate | C8: Restate | K8: Preliminary
A9: Assets
A10: Cash & Short-Term Investments | B10: 1611.4 | C10: 2263.2 | D10: 2690.9 | E10: 8937.8 | F10: 2757.1 | G10: 4632.1 | H10: 6617.9 | I10: 3182.9 | J10: 3953 | K10: 3543.2
A11: Cash Only | B11: 1530.1 | C11: 2128.8 | D11: 2462.3 | E11: 8756.3 | F11: 2686.6 | G11: 4350.9 | H11: 6455.7 | I11: 2818.4 | J11: 3551.5 | K11: 3286.2
A12: Total Short Term Investments | B12: 81.3 | C12: 134.4 | D12: 228.6 | E12: 181.5 | F12: 70.5 | G12: 281.2 | H12: 162.2 | I12: 364.5 | J12: 401.5 | K12: 257
A13: Short-Term Receivables | B13: 719 | C13: 768.8 | D13: 870.4 | E13: 1648.5 | F13: 1020.3 | G13: 1395.4 | H13: 1133.1 | I13: 1272.6 | J13: 1199.7 | K13: 1213.8
A14: Accounts Receivables, Net | B14: 719 | C14: 768.8 | D14: 870.4 | E14: 693.1 | F14: 879.2 | G14: 883.4 | H14: 940 | I14: 1175.5 | J14: 1184.1 | K14: 1213.8
A15: Accounts Receivables, Gross | B15: 729.8 | C15: 778.2 | D15: 880.2 | E15: 701.1 | F15: 879.2 | G15: 883.4 | H15: 940 | I15: 1175.5 | J15: 1184.1 | K15: 1213.8
A16: Bad Debt/Doubtful Accounts | B16: -10.8 | C16: -9.4 | D16: -9.8 | E16: -8
A17: Other Receivables | B17: 0 | C17: 0 | D17: 0 | E17: 955.4 | F17: 141.1 | G17: 512 | H17: 193.1 | I17: 97.1 | J17: 15.6 | K17: 0
A18: Inventories | B18: 1306.4 | C18: 1378.5 | D18: 1364 | E18: 1400.5 | F18: 1529.4 | G18: 1551.4 | H18: 1603.9 | I18: 2176.6 | J18: 1806.4 | K18: 1777.3
A19: Finished Goods | B19: 598 | C19: 609 | D19: 602.2 | E19: 554.3 | F19: 564.5 | G19: 517.4 | H19: 562.8 | I19: 741.2 | J19: 644.9
A20: Raw Materials | B20: 708.4 | C20: 769.5 | D20: 761.8 | E20: 846.2 | F20: 964.9 | G20: 1034 | H20: 1041.1 | I20: 1435.4 | J20: 1161.5
A21: Other Current Assets | B21: 334.2 | C21: 347.4 | D21: 358.1 | E21: 507.4 | F21: 347.1 | G21: 227.5 | H21: 401.5 | I21: 386.6 | J21: 344.3 | K21: 313.1
A22: Miscellaneous Current Assets | B22: 334.2 | C22: 347.4 | D22: 358.1 | E22: 507.4 | F22: 347.1 | G22: 227.5 | H22: 401.5 | I22: 386.6 | J22: 344.3 | K22: 313.1
A23: Total Current Assets | B23: 3971 | C23: 4757.9 | D23: 5283.4 | E23: 12494.2 | F23: 5653.9 | G23: 7806.4 | H23: 9756.4 | I23: 7018.7 | J23: 7303.4 | K23: 6847.4
A24: Net Property, Plant & Equipment | B24: 4088.3 | C24: 4533.8 | D24: 4919.5 | E24: 5929.1 | F24: 6431.7 | G24: 14375.5 | H24: 14605.5 | I24: 14576.1 | J24: 15799.7 | K24: 17951.7
A25: Property, Plant & Equipment - Gross | B25: 9641.8 | C25: 10573.3 | D25: 11584 | E25: 13197.1 | F25: 14273.5 | G25: 22289.4 | H25: 23064.8 | I25: 23625.4 | J25: 25722.8
A26: Buildings | B26: 411.5 | C26: 458.4 | D26: 481.7 | E26: 557.3 | F26: 691.5 | G26: 586.8 | H26: 587.6 | I26: 555.4 | J26: 666.5
A27: Land & Improvements | B27: 46.6 | C27: 46.6 | D27: 46.9 | E27: 46.8 | F27: 46.8 | G27: 46 | H27: 46.2 | I27: 46.1 | J27: 46.1
A28: Machinery & Equipment | B28: 2249.9 | C28: 2537.1 | D28: 2730.5 | E28: 3059 | F28: 3429.1 | G28: 3596.9 | H28: 3791.3 | I28: 3856.7 | J28: 4191.9
A29: Construction in Progress | B29: 242.5 | C29: 271.4 | D29: 409.8 | E29: 501.9 | F29: 358.5 | G29: 377.3 | H29: 374.1 | I29: 558.7 | J29: 607.5
A30: Other Property, Plant & Equipment | B30: 6691.3 | C30: 7259.8 | D30: 7915.1 | E30: 9032.1 | F30: 9747.6 | G30: 9548.3 | H30: 10029.6 | I30: 10592.9 | J30: 11798.2
A31: Operating Lease Right-of-Use Assets | G31: 8134.1 | H31: 8236 | I31: 8015.6 | J31: 8412.6 | K31: 9286.2
A32: Accumulated Depreciation | B32: 5553.5 | C32: 6039.5 | D32: 6664.5 | E32: 7268 | F32: 7841.8 | G32: 7913.9 | H32: 8459.3 | I32: 9049.3 | J32: 9923.1
A33: Total Long-Term Investments | B33: 664.5 | C33: 1496.2 | D33: 1023.9 | E33: 602.4 | F33: 616 | G33: 684.8 | H33: 634.5 | I33: 746.5 | J33: 840.3 | K33: 739.9
A34: LT Investment - Affiliate Companies | B34: 352 | C34: 354.5 | D34: 481.6 | E34: 334.7 | F34: 396 | G34: 478.7 | H34: 268.5 | I34: 311.2 | J34: 439.9
A35: Other Long-Term Investments | B35: 312.5 | C35: 1141.7 | D35: 542.3 | E35: 267.7 | F35: 220 | G35: 206.1 | H35: 366 | I35: 435.3 | J35: 400.4 | K35: 739.9
A36: Intangible Assets | B36: 2095.8 | C36: 2235.9 | D36: 1980.6 | E36: 4583.8 | F36: 4272.6 | G36: 4149.3 | H36: 4027.2 | I36: 3439.4 | J36: 3338.8 | K36: 3416.6
A37: Goodwill | B37: 1575.4 | C37: 1719.6 | D37: 1539.2 | E37: 3541.6 | F37: 3490.8 | G37: 3597.2 | H37: 3677.3 | I37: 3283.5 | J37: 3218.3 | K37: 3315.7
A38: Other Intangible Assets | B38: 520.4 | C38: 516.3 | D38: 441.4 | E38: 1042.2 | F38: 781.8 | G38: 552.1 | H38: 349.9 | I38: 155.9 | J38: 120.5 | K38: 100.9
A39: Deferred Tax Assets | B39: 1180.8 | C39: 885.4 | D39: 795.4 | E39: 134.7 | F39: 1765.8 | G39: 1789.9 | H39: 1874.8 | I39: 1799.7 | J39: 1769.8 | K39: 1766.7
A40: Other Assets | B40: 415.9 | C40: 403.3 | D40: 362.8 | E40: 412.2 | F40: 479.6 | G40: 568.6 | H40: 494.2 | I40: 398 | J40: 393.5 | K40: 617
A41: Tangible Other Assets | B41: 415.9 | C41: 403.3 | D41: 362.8 | E41: 412.2 | F41: 479.6 | G41: 568.6 | H41: 494.2 | I41: 398 | J41: 393.5 | K41: 617
...

Sheet IS
A1: Starbucks Corporation (SBUX)
A2: $99.05
A5: Starbucks Corporation
A6: SBUX 855244109 2842255 NASDAQ Common stock
A7: Source: FactSet Fundamentals
B8: SEP '15 | C8: SEP '16 | D8: SEP '17 | E8: SEP '18 | F8: SEP '19 | G8: SEP '20 | H8: SEP '21 | I8: SEP '22 | J8: SEP '23 | K8: SEP '24
B9: Restate | C9: Restate | K9: Preliminary
A10: Sales | B10: 19148.7 | C10: 21311 | D10: 22383.8 | E10: 24719.9 | F10: 26501.6 | G10: 23512.5 | H10: 29058.8 | I10: 32228.3 | J10: 35952 | K10: 36176.2
A11: Cost of Goods Sold (COGS) incl. D&A | B11: 14585.2 | C11: 16041 | D11: 17039.3 | E11: 19104.8 | F11: 20772.9 | G11: 20316.3 | H11: 22461.7 | I11: 25919 | J11: 28136.3 | K11: 28545.3
A12: COGS excluding D&A | B12: 13651.4 | C12: 15010.9 | D12: 15972.2 | E12: 17798.9 | F12: 19323.6 | G12: 17615.5 | H12: 19689 | I12: 22891.9 | J12: 26686 | K12: 25717.8
A13: Depreciation & Amortization Expense | B13: 933.8 | C13: 1030.1 | D13: 1067.1 | E13: 1305.9 | F13: 1449.3 | G13: 2700.8 | H13: 2772.7 | I13: 3027.1 | J13: 1450.3 | K13: 2827.5
A14: Depreciation | B14: 883.8 | C14: 972.8 | D14: 1009.6 | E14: 1119.4 | F14: 1216.5 | G14: 2477.1 | H14: 2549.3 | I14: 2834.4 | J14: 1428.8
A15: Amortization of Intangibles | B15: 50 | C15: 57.3 | D15: 57.5 | E15: 186.5 | F15: 232.8 | G15: 223.7 | H15: 223.4 | I15: 192.7 | J15: 21.5
A16: Gross Income | B16: 4563.5 | C16: 5270 | D16: 5344.5 | E16: 5615.1 | F16: 5728.7 | G16: 3196.2 | H16: 6597.1 | I16: 6309.3 | J16: 7815.7 | K16: 7630.9
A17: SG&A Expense | B17: 1196.7 | C17: 1360.6 | D17: 1393.3 | E17: 1755.4 | F17: 1824.1 | G17: 1679.6 | H17: 1932.6 | I17: 2032 | J17: 2441.3 | K17: 2523.3
A18: Other SG&A | B18: 1196.7 | C18: 1360.6 | D18: 1393.3 | E18: 1755.4 | F18: 1824.1 | G18: 1679.6 | H18: 1932.6 | I18: 2032 | J18: 2441.3 | K18: 2523.3
A19: EBIT (Operating Income) | B19: 3366.8 | C19: 3909.4 | D19: 3951.2 | E19: 3859.7 | F19: 3904.6 | G19: 1516.6 | H19: 4664.5 | I19: 4277.3 | J19: 5374.4 | K19: 5107.6
A20: Nonoperating Income - Net | B20: 296.4 | C20: 407.4 | D20: 622.1 | E20: 1025.5 | F20: 1049.1 | G20: 387.6 | H20: 1336 | I20: 429 | J20: 642.4 | K20: 424
A21: Nonoperating Interest Income | B21: 0 | C21: 215.3 | D21: 126.5 | E21: 259.9 | F21: 132.2 | G21: 49.9 | H21: 70.9 | I21: 0 | J21: 0 | K21: 122.8
A22: Equity in Earnings of Affiliates | B22: 249.9 | C22: 318.2 | D22: 391.4 | E22: 301.2 | F22: 298 | G22: 322.5 | H22: 385.3 | I22: 234.1 | J22: 298.4 | K22: 301.2
A23: Other Income (Expense) | B23: 46.5 | C23: -126.1 | D23: 104.2 | E23: 464.4 | F23: 618.9 | G23: 15.2 | H23: 879.8 | I23: 194.9 | J23: 344 | K23: 0
A24: Interest Expense | B24: 73.7 | C24: 86.3 | D24: 97.3 | E24: 175.2 | F24: 339.8 | G24: 457.5 | H24: 496.8 | I24: 497.2 | J24: 551 | K24: 562 | L24: =K24/BS!K54 -> 0.024338381
A25: Gross Interest Expense | B25: 77.3 | C25: 86.3 | D25: 97.3 | E25: 175.2 | F25: 339.8 | G25: 457.5 | H25: 496.8 | I25: 497.2 | J25: 551 | K25: 562
A26: Interest Capitalized | B26: 3.6 | C26: 0 | D26: 0 | E26: 0 | F26: 0 | G26: 0 | H26: 0 | I26: 0 | J26: 0
A27: Unusual Expense - Net | B27: -313.5 | C27: 31.9 | D27: 158.5 | E27: -1070 | F27: 147.7 | G27: 282.3 | H27: 146.8 | I27: -22.8 | J27: 63.9 | K27: 0
A28: Impairments | B28: 25.8 | C28: 24.1 | D28: 16.2 | E28: 43.4
A29: Goodwill | B29: 0 | C29: 0 | D29: 0 | E29: 37.6 | F29: 0 | G29: 0 | H29: 0 | I29: 0 | J29: 0
A30: Property,Plant & Equipment | B30: 25.8 | C30: 24.1 | D30: 16.2 | E30: 5.8
A31: Restructuring Expense | B31: 0 | C31: 0 | D31: 153.5 | E31: 228 | F31: 135.8 | G31: 278.7 | H31: 170.4 | I31: 46 | J31: 21.8 | K31: 0
A32: Unrealized Valuation Gain/Loss | B32: 400.4 | C32: -7.8 | D32: 11.2 | E32: 1341.4 | F32: -11.9 | G32: -3.6 | H32: 23.6 | I32: 68.8 | J32: -42.1
A33: Investments | B33: 386.1 | C33: 3.6 | D33: 10.5 | E33: 1369.2 | F33: 0 | G33: 0
A34: Hedges/Derivatives | B34: 14.3 | C34: -11.4 | D34: 0.7 | E34: -27.8 | F34: -11.9 | G34: -3.6 | H34: 23.6 | I34: 68.8 | J34: -42.1
A35: Excpl Chrgs - Others | B35: 61.1 | C35: 0 | D35: 0
A36: Restructuring of Debt | B36: 61.1 | C36: 0 | D36: 0
A37: Pretax Income | B37: 3903 | C37: 4198.6 | D37: 4317.5 | E37: 5780 | F37: 4466.2 | G37: 1164.4 | H37: 5356.9 | I37: 4231.9 | J37: 5401.9 | K37: 4969.6
A38: Income Taxes | B38: 1143.7 | C38: 1379.7 | D38: 1432.6 | E38: 1262 | F38: 871.6 | G38: 239.7 | H38: 1156.6 | I38: 948.5 | J38: 1277.2 | K38: 1207.3
A39: Income Taxes - Current Domestic | B39: 951.1 | C39: 870.6 | D39: 1101.8 | E39: 208.2 | F39: 1862.1 | G39: 86.8 | H39: 871.8 | I39: 641.6 | J39: 914.1
A40: Income Taxes - Current Foreign | B40: 172.2 | C40: 218.5 | D40: 216.6 | E40: 327 | F40: 458.3 | G40: 181.4 | H40: 409.8 | I40: 283.8 | J40: 422.4
A41: Income Taxes - Deferred Domestic | B41: 60.5 | C41: 377.1 | D41: 135.4 | E41: 735.2 | F41: -1396.9 | G41: -13.2 | H41: 4 | I41: 103.1 | J41: 116.2
A42: Income Taxes - Deferred Foreign | B42: -40.1 | C42: -86.5 | D42: -21.2 | E42: -8.4 | F42: -51.9 | G42: -15.3 | H42: -129 | I42: -80 | J42: -175.5
...

Sheet IS Estimates
A1: SBUX-USA
A2: Income Statement (M) | B2: =B13/B4 -> 0.14248235 | C2: =C13/C4 -> 0.22371871 | D2: =D13/D4 -> 0.19025559 | E2: =E13/E4 -> 0.19913775 | F2: =F13/F4 -> 0.19132192 | G2: =G13/G4 -> 0.18608022 | H2: =H13/H4 -> 0.19454843 | I2: =I13/I4 -> 0.20360286 | ... L2: =L13/L4 -> 0.22168
B3: Sep '20 | C3: Sep '21 | D3: Sep '22 | E3: Sep '23 | F3: Sep '24 | G3: Sep '25E | H3: Sep '26E | I3: Sep '27E | J3: Sep '28E | K3: Sep '29E | L3: Sep '30E
A4: Sales | B4: 23518 | C4: 29060.6 | D4: 32250.3 | E4: 35975.6 | F4: 36176.2 | G4: 37609.8 | H4: 40111.4 | I4: 43529.3 | J4: 46596.6 | K4: 50804.9 | L4: 55020.3
A5: Sharp Consensus | B5: 0 | C5: 0 | D5: 0 | E5: 0 | F5: 0 | G5: 37331.6 | H5: 0 | I5: 0 | J5: 0 | K5: 0 | L5: 0
A6: Guidance (Low) | B6: 0 | C6: 29100 | D6: 0 | E6: 0 | F6: 36176.2 | G6: 0 | H6: 0 | I6: 0 | J6: 0 | K6: 0 | L6: 0
A7: Guidance (High) | B7: 0 | C7: 29300 | D7: 0 | E7: 0 | F7: 0 | G7: 0 | H7: 0 | I7: 0 | J7: 0 | K7: 0 | L7: 0
A8: Cost of Sales | B8: 7694.9 | C8: 8738.6 | D8: 10317.3 | E8: 11409.2 | F8: 11180.5 | G8: 11449.8 | H8: 12020.8 | I8: 12845.3 | J8: 14200.8 | K8: 15357.9 | L8: 16585.5
A9: Gross Income | B9: 15823.1 | C9: 20322 | D9: 21933 | E9: 24566.4 | F9: 24995.7 | G9: 25863.9 | H9: 27418.7 | I9: 30062.3 | J9: 32649.4 | K9: 35447 | L9: 38434.8
A10: SG&A Expense | B10: 1663 | C10: 1908 | D10: 2032 | E10: 2441.15 | F10: 2523 | G10: 2554.9 | H10: 2662 | I10: 0 | J10: 0 | K10: 0 | L10: 0
A11: Selling & Marketing Expense | B11: 0 | C11: 8739 | D11: 10317.2 | E11: 11409 | F11: 11180.5 | G11: 11582.9 | H11: 12227.3 | I11: 13105.8 | J11: 14085 | K11: 0 | L11: 0
A12: General & Admin Expense | B12: 1663.3 | C12: 1910.4 | D12: 2031.9 | E12: 2441.4 | F12: 2523.4 | G12: 2562.13 | H12: 2627.21 | I12: 2729.38 | J12: 2901.95 | K12: 3219.1 | L12: 3418
A13: EBITDA | B13: 3350.9 | C13: 6501.4 | D13: 6135.8 | E13: 7164.1 | F13: 6921.3 | G13: 6998.44 | H13: 7803.61 | I13: 8862.69 | J13: 9810.3 | K13: 10945.9 | L13: 12196.9
A14: EBITDA Non-GAAP | B14: 3350.6 | C14: 6537.8 | D14: 6135.8 | E14: 7164.1 | F14: 6921.3 | G14: 7038.74 | H14: 7815.4 | I14: 8913.49 | J14: 9810.3 | K14: 10945.9 | L14: 12196.9
A15: EBITDA GAAP | B15: 3064.8 | C15: 6438.3 | D15: 6134.8 | E15: 7164.7 | F15: 6921.3 | G15: 6856.29 | H15: 7501.08 | I15: 8855.65 | J15: 0 | K15: 0 | L15: 0
... A35: Net Income - GAAP | B35: 928.3 | C35: 4199.3 | D35: 3281.6 | E35: 4124.5 | F35: 3760.9 | G35: 3718.36 | H35: 4449.06 | I35: 4889.48 | J35: 5858 | K35: 0 | L35: 0
A38: Tax rate | B38: =B32/B29 -> 0.20276498 | C38: =C32/C29 -> 0.21480359 | D38: =D32/D29 -> 0.23088911 | E38: =E32/E29 -> 0.23565405 | F38: =F32/F29 -> 0.24294195 | G38: =G32/G29 -> 0.24110415 | H38: =H32/H29 -> 0.23928176 | I38: =I32/I29 -> 0.24198113 | ... L38: =L32/L29 -> 0.24499431

Sheet BS Estimates
A1: SBUX-USA
A2: Balance Sheet (M)
B3: Sep '20 | C3: Sep '21 | D3: Sep '22 | E3: Sep '23 | F3: Sep '24 | G3: Sep '25E | H3: Sep '26E | I3: Sep '27E | J3: Sep '28E | K3: Sep '29E | L3: Sep '30E
A4: Current Assets | B4: 7806 | C4: 9756 | D4: 7019 | E4: 7303 | F4: 6847 | G4: 6005.5 | H4: 6869.22 | I4: 10337.5 | J4: 14289 | K4: - | L4: -
A5: Current Liabilities | B5: 7346.8 | C5: 8151.4 | D5: 9151.8 | E5: 9345.15 | F5: 9070 | G5: 8823.77 | H5: 9035.9 | I5: 10006.5 | J5: 11729 | K5: - | L5: -
A6: Total Assets | B6: 29374.5 | C6: 31392.6 | D6: 27978 | E6: 29445.8 | F6: 31339.2 | G6: 31901.9 | H6: 34250.6 | I6: 39681.8 | J6: 46608 | K6: - | L6: -
A7: Short-Term Debt | B7: 1469.45 | C7: 998.9 | D7: 1749 | E7: 1818.6 | F7: 1248.95 | G7: 1067.16 | H7: 1132.47 | I7: 1025 | J7: 2371 | K7: - | L7: -
A8: Long-Term Debt | B8: 14659.6 | C8: 13616.9 | D8: 13120 | E8: 13547.6 | F8: 14319.5 | G8: 14886 | H8: 17568.4 | I8: 21911.8 | J8: 27185 | K8: - | L8: -
A9: Total Debt | B9: 16348 | C9: 14616 | D9: 14869 | E9: 15399.8 | F9: 15568 | G9: 15595.5 | H9: 16578.8 | I9: 21568.4 | J9: - | K9: - | L9: -
A10: Intangible Assets | B10: 552.1 | C10: 349.9 | D10: 156 | E10: 120.75 | F10: 101 | G10: 754.08 | H10: 904.875 | I10: 100.95 | J10: 101 | K10: - | L10: -
A11: Total Goodwill | B11: 3597.2 | C11: 3677.3 | D11: 3283.5 | E11: 3218.3 | F11: 3315.7 | G11: 3315.8 | H11: 3315.82 | I11: 3315.8 | J11: 3316 | K11: - | L11: -
A12: Net Debt | B12: 11716.2 | C12: 7998 | D12: 11686 | E12: 11848.1 | F12: 12153.6 | G12: 16703 | H12: 17375.5 | I12: 19378.2 | J12: - | K12: - | L12: -
A13: Working Capital | B13: 460 | C13: 1605 | D13: -2133.05 | E13: -2041.95 | F13: -2222.8 | G13: -2733.56 | H13: -2708.92 | I13: - | J13: - | K13: - | L13: -
A14: Minority Interest | B14: 5.7 | C14: 6.7 | D14: 7.9 | E14: 7 | F14: 7.3 | G14: 7.18 | H14: 7.15 | I14: 7 | J14: 7 | K14: - | L14: -
A15: Shareholder Equity | B15: -7805 | C15: -5314.5 | D15: -8698.85 | E15: -7987.8 | F15: -7445.25 | G15: -7395.85 | H15: -7458.18 | I15: -6670.97 | J15: -9398 | K15: - | L15: -

Sheet CFS Estimates
A1: SBUX-USA
A2: Cash Flow (M)
B3: Sep '20 | C3: Sep '21 | D3: Sep '22 | E3: Sep '23 | F3: Sep '24 | G3: Sep '25E | H3: Sep '26E | I3: Sep '27E | J3: Sep '28E | K3: Sep '29E | L3: Sep '30E
A4: Capital Expenditures | B4: 1483.6 | C4: 1470 | D4: 1841.3 | E4: 2333.6 | F4: 2777.5 | G4: 2707.57 | H4: 2978.22 | I4: 3359.48 | J4: 3833 | K4: - | L4: -
A5: Guidance (Low) | B5: 1500 | C5: 1700 | D5: - | E5: 2500 | F5: 3000 | G5: - | H5: - | I5: - | J5: - | K5: - | L5: -
A6: Free Cash Flow | B6: 114.2 | C6: 4519 | D6: 2556 | E6: 3675.1 | F6: 3318.1 | G6: 3389.53 | H6: 3871.72 | I6: 4034.89 | J6: - | K6: - | L6: -
A7: Cash Flow from Operations | B7: 1597.9 | C7: 5989.1 | D7: 4397 | E7: 6008.85 | F7: 6095.8 | G7: 5740.85 | H7: 6660.04 | I7: 7766.15 | J7: 9490 | K7: - | L7: -
A8: Cash Flow from Investing | B8: -1711.5 | C8: -319.5 | D8: -2146.3 | E8: -2270.8 | F8: -2699.2 | G8: -2795.06 | H8: -3170 | I8: -3644.5 | J8: -3877 | K8: - | L8: -
A9: Cash Flow from Financing | B9: 1713.3 | C9: -3651 | D9: -5638 | E9: -2990.6 | F9: -3718.2 | G9: -3344.38 | H9: -2791.68 | I9: -2768.05 | J9: -3784 | K9: - | L9: -
