Workbook
Name D: WACC!$D$15
Name D_perc: WACC!$D$17
Name E: WACC!$D$14
Name E_perc: WACC!$D$16
Name kd: WACC!$D$19
Name ke: WACC!$D$12
Name scen: 'DCF model'!$E$16
Name Tax_shield: WACC!$D$18
Name Tax_shielf: WACC!$D$18
Name Tgr: 'DCF model'!$E$18
Name wacc: 'DCF model'!$E$17

Sheet Agenda
C3: Agenda
B6: 1 | C6: DCF | E6: X
B7: 2 | C7: Comps analysis
B8: 3 | C8: Past transactions
B9: 3 | C9: Football chart

Sheet DCF model
C3: DCF model
A6: • | C6: Overview
C8: Comp name | E8: McDonald's Corporation | G8: Valuation | I8: =R98 -> 270.50981
C9: Ticker | E9: MCD | G9: % delta vs current | I9: =I8/E11-1 -> -0.12865256
C10: Date | E10: =TODAY() -> 45986
C11: Price per share | E11: 310.45
A13: • | C13: Assumptions
C15: Triggers | G15: Conservative | H15: Year | I15: Amount | K15: Base / Street | L15: Year | M15: Amount | O15: Optimistic | P15: Year | Q15: Amount
C16: Scenario | E16: 1 | G16: Revenue gr | H16: 25-'30 | I16: -0.2 | O16: Revenue gr | P16: 25-'30 | Q16: 0.55
C17: WACC | E17: =CHOOSE(scen,M20,I20,Q20) -> 0.061305018 | G17: EBITDA margin | H17: 25 | I17: -0.05 | O17: EBITDA margin | P17: 25 | Q17: 0
C18: TGR | E18: =CHOOSE(scen,M21,I21,Q21) -> 0.025 | G18: EBITDA margin | H18: 30 | I18: -0.15 | O18: EBITDA margin | P18: 30 | Q18: 0.05
G19: D&A | H19: 25 | I19: 0 | O19: D&A | P19: 25-'30 | Q19: 0
G20: WACC | I20: 0.062 | K20: WACC | M20: =WACC!D21 -> 0.061305018 | O20: WACC | Q20: 0.06
G21: TGR | I21: 0.022 | K21: TGR | M21: 0.025 | O21: TGR | Q21: 0.028
A23: • | C23: Income statement
H25: Actuals | M25: Projections
C26: $M | H26: 2020 | I26: =+H26+1 -> 2021 | J26: =+I26+1 -> 2022 | K26: =+J26+1 -> 2023 | L26: =+K26+1 -> 2024 | M26: =+L26+1 -> 2025 | N26: =+M26+1 -> 2026 | O26: =+N26+1 -> 2027 | P26: =+O26+1 -> 2028 | ... R26: =+Q26+1 -> 2030
C27: Revenue | H27: =IS!H11 -> 16849 | I27: =IS!I11 -> 19647 | J27: =IS!J11 -> 22058 | K27: =IS!K11 -> 23581 | L27: =IS!L11 -> 23962 | M27: =L27*(1+M28) -> 24561.05 | N27: =M27*(1+N28) -> 25175.076 | O27: =N27*(1+O28) -> 25804.453 | P27: =O27*(1+P28) -> 26449.564 | Q27: =P27*(1+Q28) -> 27110.804 | R27: =Q27*(1+R28) -> 27788.574
C28: % growth | I28: =I27/H27-1 -> 0.16606327 | J28: =J27/I27-1 -> 0.12271594 | K28: =K27/J27-1 -> 0.069045244 | L28: =L27/K27-1 -> 0.016157076 | M28: =OFFSET(M28,scen,0) -> 0.025 | N28: =OFFSET(N28,scen,0) -> 0.025 | O28: =OFFSET(O28,scen,0) -> 0.025 | P28: =OFFSET(P28,scen,0) -> 0.025 | Q28: =OFFSET(Q28,scen,0) -> 0.025 | R28: =OFFSET(R28,scen,0) -> 0.025
C29: 1. Base | M29: 0.025 | N29: =M29 -> 0.025 | O29: =N29 -> 0.025 | P29: =O29 -> 0.025 | Q29: =P29 -> 0.025 | R29: =Q29 -> 0.025
C30: 2. Conservative | M30: =M29*(1+I16) -> 0.02 | N30: =M30 -> 0.02 | O30: =N30 -> 0.02 | P30: =O30 -> 0.02 | Q30: =P30 -> 0.02 | R30: =Q30 -> 0.02
C31: 3. Optimistic | M31: =M29*(1+Q16) -> 0.03875 | N31: =M31 -> 0.03875 | O31: =N31 -> 0.03875 | P31: =O31 -> 0.03875 | Q31: =P31 -> 0.03875 | R31: =Q31 -> 0.03875
C33: COGS | H33: =IS!H13*-1 -> -6788 | I33: =IS!I13*-1 -> -7482 | J33: =IS!J13*-1 -> -7831 | K33: =IS!K13*-1 -> -8419 | L33: =IS!L13*-1 -> -8525 | M33: =M35-M27 -> -8524.4558 | N33: =N35-N27 -> -8540.3171 | O33: =O35-O27 -> -8583.3187 | P33: =P35-P27 -> -8621.3851 | Q33: =Q35-Q27 -> -8654.1808 | R33: =R35-R27 -> -8681.355
C35: Gross profit | H35: =H27+H33 -> 10061 | I35: =I27+I33 -> 12165 | J35: =J27+J33 -> 14227 | K35: =K27+K33 -> 15162 | L35: =L27+L33 -> 15437 | M35: =M27*M36 -> 16036.594 | N35: =N27*N36 -> 16634.759 | O35: =O27*O36 -> 17221.134 | P35: =P27*P36 -> 17828.179 | Q35: =Q27*Q36 -> 18456.623 | R35: =R27*R36 -> 19107.219
C36: % margin | H36: =H35/H$27 -> 0.59712743 | I36: =I35/I$27 -> 0.6191785 | J36: =J35/J$27 -> 0.64498141 | K36: =K35/K$27 -> 0.64297528 | L36: =L35/L$27 -> 0.64422836 | M36: =L36*(1+M37) -> 0.65292788 | N36: =M36*(1+N37) -> 0.66076301 | O36: =N36*(1+O37) -> 0.66737064 | P36: =O36*(1+P37) -> 0.67404435 | Q36: =P36*(1+Q37) -> 0.68078479 | R36: =Q36*(1+R37) -> 0.68759264
C37: % growth | I37: =I36/H36-1 -> 0.036928591 | J37: =J36/I36-1 -> 0.041672817 | K37: =K36/J36-1 -> -0.0031103779 | L37: =L36/K36-1 -> 0.001948885 | M37: =OFFSET(M37,scen,0) -> 0.013503775 | N37: =OFFSET(N37,scen,0) -> 0.012 | O37: =OFFSET(O37,scen,0) -> 0.01 | P37: =OFFSET(P37,scen,0) -> 0.01 | Q37: =OFFSET(Q37,scen,0) -> 0.01 | R37: =OFFSET(R37,scen,0) -> 0.01
C38: 1. Base | M38: =AVERAGE(J37:L37) -> 0.013503775 | N38: 0.012 | O38: 0.01 | P38: =O38 -> 0.01 | Q38: =P38 -> 0.01 | R38: =Q38 -> 0.01
C39: 2. Conservative | M39: =AVERAGE(K37:L37) -> -0.00058074646 | N39: =M39 -> -0.00058074646 | O39: =N39 -> -0.00058074646 | P39: 0 | Q39: 0 | R39: 0
C40: 3. Optimistic | M40: 0.03 | N40: =M40 -> 0.03 | O40: =N40 -> 0.03 | P40: =O40 -> 0.03 | Q40: =P40 -> 0.03 | R40: =Q40 -> 0.03
C42: Opex | H42: =IS!H18*-1 -> -2243 | I42: =IS!I18*-1 -> -2316 | J42: =IS!J18*-1 -> -2595 | K42: =IS!K18*-1 -> -2492 | L42: =IS!L18*-1 -> -2535 | M42: =M45-M35 -> -2564.2299 | N42: =N45-N35 -> -2667.7931 | O42: =O45-O35 -> -2734.7251 | P42: =P45-P35 -> -3001.1252 | Q42: =Q45-Q35 -> -2810.39 | R42: =R45-R35 -> -2922.4242
C43: % sales | H43: =H42/H27*-1 -> 0.13312363 | I43: =I42/I27*-1 -> 0.11788059 | J43: =J42/J27*-1 -> 0.11764439 | K43: =K42/K27*-1 -> 0.1056783 | L43: =L42/L27*-1 -> 0.1057925 | M43: =M42/M27*-1 -> 0.10440229 | N43: =N42/N27*-1 -> 0.10596962 | O43: =O42/O27*-1 -> 0.10597881 | ... R43: =R42/R27*-1 -> 0.1051664
C45: EBITDA | H45: =H35+H42 -> 7818 | I45: =I35+I42 -> 9849 | J45: =J35+J42 -> 11632 | K45: =K35+K42 -> 12670 | L45: =L35+L42 -> 12902 | M45: =M27*M46 -> 13472.364 | N45: =N27*N46 -> 13966.966 | O45: =O27*O46 -> 14486.409 | P45: =P27*P46 -> 14827.054 | Q45: =Q27*Q46 -> 15646.233 | R45: =R27*R46 -> 16184.794
C46: % margin | H46: =H45/H$27 -> 0.4640038 | I46: =I45/I$27 -> 0.50129791 | J46: =J45/J$27 -> 0.52733702 | K46: =K45/K$27 -> 0.53729698 | L46: =L45/L$27 -> 0.53843586 | M46: =OFFSET(M46,scen,0) -> 0.54852559 | N46: =OFFSET(N46,scen,0) -> 0.5547934 | O46: =OFFSET(O46,scen,0) -> 0.56139184 | P46: =OFFSET(P46,scen,0) -> 0.56057839 | Q46: =OFFSET(Q46,scen,0) -> 0.57712169 | R46: =OFFSET(R46,scen,0) -> 0.58242624
C47: 1. Base | M47: ='Estimates IS'!H14 -> 0.54852559 | N47: ='Estimates IS'!I14 -> 0.5547934 | O47: ='Estimates IS'!J14 -> 0.56139184 | P47: ='Estimates IS'!K14 -> 0.56057839 | Q47: ='Estimates IS'!L14 -> 0.57712169 | R47: ='Estimates IS'!M14 -> 0.58242624
C48: 2. Conservative | M48: =M47*(1+I17) -> 0.52109931 | N48: =M48-(($M$48-$R$48)/($R$26-$M$26)) -> 0.51589191 | O48: =N48-(($M$48-$R$48)/($R$26-$M$26)) -> 0.5106845 | P48: =O48-(($M$48-$R$48)/($R$26-$M$26)) -> 0.5054771 | Q48: =P48-(($M$48-$R$48)/($R$26-$M$26)) -> 0.5002697 | R48: =R47*(1+I18) -> 0.4950623
C49: 3. Optimistic | M49: =M47*(1+Q17) -> 0.54852559 | N49: =M49+(($R$49-$M$49)/($R$26-$M$26)) -> 0.56112998 | O49: =N49+(($R$49-$M$49)/($R$26-$M$26)) -> 0.57373437 | P49: =O49+(($R$49-$M$49)/($R$26-$M$26)) -> 0.58633876 | Q49: =P49+(($R$49-$M$49)/($R$26-$M$26)) -> 0.59894316 | R49: =R47*(1+Q18) -> 0.61154755
C51: D&A | H51: =IS!H14*-1 -> -1536 | I51: =IS!I14*-1 -> -1580 | J51: =IS!J14*-1 -> -1780 | K51: =IS!K14*-1 -> -1830 | L51: =IS!L14*-1 -> -1939 | M51: =M27*M52*-1 -> -2005.5706 | N51: =N27*N52*-1 -> -2029.8478 | O51: =O27*O52*-1 -> -2103.827 | P51: =P27*P52*-1 -> -2051.1496 | Q51: =Q27*Q52*-1 -> -1800.6914 | R51: =R27*R52*-1 -> -1770.1186
C52: % sales | H52: =H51/H$27*-1 -> 0.09116268 | I52: =I51/I$27*-1 -> 0.080419402 | J52: =J51/J$27*-1 -> 0.080696346 | K52: =K51/K$27*-1 -> 0.077604851 | L52: =L51/L$27*-1 -> 0.08091979 | M52: =OFFSET(M52,scen,0) -> 0.081656548 | N52: =OFFSET(N52,scen,0) -> 0.080629261 | O52: =OFFSET(O52,scen,0) -> 0.08152961 | P52: =OFFSET(P52,scen,0) -> 0.077549467 | Q52: =OFFSET(Q52,scen,0) -> 0.066419698 | R52: =OFFSET(R52,scen,0) -> 0.063699513
C53: 1. Base | M53: ='Estimates IS'!H18 -> 0.081656548 | N53: ='Estimates IS'!I18 -> 0.080629261 | O53: ='Estimates IS'!J18 -> 0.08152961 | P53: ='Estimates IS'!K18 -> 0.077549467 | Q53: ='Estimates IS'!L18 -> 0.066419698 | R53: ='Estimates IS'!M18 -> 0.063699513
C54: 2. Conservative | M54: =M53*(1+I19) -> 0.081656548 | N54: =M54 -> 0.081656548 | O54: =N54 -> 0.081656548 | P54: =O54 -> 0.081656548 | Q54: =P54 -> 0.081656548 | R54: =Q54 -> 0.081656548
...

Sheet INPUT>>

Sheet WACC
C3: WACC
C5: WACC = kE*(E/E+D) + kd * D/D+E * (1-tax)
C6: Ke = Rf + Beta * (Rm - Rf)
C7: Rm - Rf = MRP
C9: Rf | D9: 0.0438 | F9: 10-yr treas yield - google
C10: Beta | D10: 0.57 | F10: Factset
C11: MRP | D11: 0.046 | F11: Damodoran
C12: Ke | D12: =D9+D10*D11 -> 0.07002
C14: E | D14: 217140 | F14: Factset
C15: D | D15: =BS!L48 -> 49552.872 | F15: BS
C16: E% | D16: =E/(SUM(D14:D15)) -> 0.81419499
C17: D% | D17: =D/SUM(D14:D15) -> 0.18580501
C18: 1-Tax | D18: =(1-'DCF model'!M67) -> 0.79823581
C19: Kd | D19: =IS!L25/D -> 0.028958968
C21: WACC | D21: =ke*E_perc+kd*Tax_shield*D_perc -> 0.061305018

Sheet Estimates IS
B1: MCD-US
B2: Income Statement (M)
C3: Dec '20 | D3: Dec '21 | E3: Dec '22 | F3: Dec '23 | G3: Dec '24 | H3: Dec '25E | I3: Dec '26E | J3: Dec '27E | K3: Dec '28E | L3: Dec '29E | M3: Dec '30E
B4: Sales | C4: 15845 | D4: 20830 | E4: 21346 | F4: 23769 | G4: 25127 | H4: 23060 | I4: 24346 | J4: 25549 | K4: 26280 | L4: 26724 | M4: 27928
B5: Cost of Sales | C5: 5759 | D5: 7218 | E5: 6796 | F5: 7668 | G5: 8079 | H5: 7100 | I5: 7503 | J5: 7846 | K5: - | L5: - | M5: -
B6: Gross Income | C6: - | D6: 10463 | E6: 11493 | F6: 13578 | G6: - | H6: 12019 | I6: 12871 | J6: - | K6: - | L6: - | M6: -
B7: Compensation and Benefits | C7: - | D7: - | E7: - | F7: - | G7: - | H7: 2212 | I7: 2328 | J7: - | K7: - | L7: - | M7: -
B8: EBITDA | C8: 7314 | D8: 10722 | E8: 11281 | F8: 12964 | G8: 13602 | H8: 12649 | I8: 13507 | J8: 14343 | K8: 14732 | L8: 15423 | M8: 16266
B9: Operating Income | C9: 5890 | D9: 9158 | E9: 9558 | F9: 11114 | G9: 11634 | H9: 10766 | I9: 11544 | J9: 12260 | K9: 12694 | L9: 13648 | M9: 14487
B10: Pretax Income | C10: 4926 | D10: 7998 | E10: 8595 | F10: 9820 | G10: 10258 | H10: 9456 | I10: 10235 | J10: 10972 | K10: 11366 | L10: 12298 | M10: 13128
B11: Tax Expense | C11: 1163 | D11: 1609 | E11: 1517 | F11: 1915 | G11: 2056 | H11: 2020 | I11: 2158 | J11: 2327 | K11: 2418 | L11: 2582 | M11: 2757
B12: Net Income | C12: 3744 | D12: 6258 | E12: 6892 | F12: 8151 | G12: 8200 | H12: 7465 | I12: 8083 | J12: 8675 | K12: 8988 | L12: 9813 | M12: 10466
B14: % margin EBITDA | H14: =H8/H4 -> 0.54852559 | I14: =I8/I4 -> 0.5547934 | J14: =J8/J4 -> 0.56139184 | K14: =K8/K4 -> 0.56057839 | L14: =L8/L4 -> 0.57712169 | M14: =M8/M4 -> 0.58242624
H15: =H8-H6 -> 630 | I15: =I8-I6 -> 636 | J15: =J8-J6 -> #VALUE! | K15: =K8-K6 -> #VALUE! | L15: =L8-L6 -> #VALUE! | M15: =M8-M6 -> #VALUE!
H17: =H8-H9 -> 1883 | I17: =I8-I9 -> 1963 | J17: =J8-J9 -> 2083 | K17: =K8-K9 -> 2038 | L17: =L8-L9 -> 1775 | M17: =M8-M9 -> 1779
H18: =H17/H4 -> 0.081656548 | I18: =I17/I4 -> 0.080629261 | J18: =J17/J4 -> 0.08152961 | K18: =K17/K4 -> 0.077549467 | L18: =L17/L4 -> 0.066419698 | M18: =M17/M4 -> 0.063699513
H20: =H12/H4 -> 0.32372073 | I20: =I12/I4 -> 0.33200526 | J20: =J12/J4 -> 0.33954362 | K20: =K12/K4 -> 0.34200913 | L20: =L12/L4 -> 0.36719802 | M20: =M12/M4 -> 0.37474936
B25: Capex | C25: 1354 | D25: 1830 | E25: 1749 | F25: 2198 | G25: 2690 | H25: 2707 | I25: 2928 | J25: 3261 | K25: 3525 | L25: =K25*(1+L27) -> 3774.0819 | M25: =L25*(1+M27) -> 4040.7644
B26: % sales | C26: =C25/C4 -> 0.085452824 | D26: =D25/D4 -> 0.087854057 | E26: =E25/E4 -> 0.081935726 | F26: =F25/F4 -> 0.09247339 | G26: =G25/G4 -> 0.10705615 | H26: =H25/H4 -> 0.11738942 | I26: =I25/I4 -> 0.12026616 | J26: =J25/J4 -> 0.12763709 | K26: =K25/K4 -> 0.13413242
B27: % growth | D27: =D25/C25-1 -> 0.35155096 | E27: =E25/D25-1 -> -0.044262295 | F27: =F25/E25-1 -> 0.25671812 | G27: =G25/F25-1 -> 0.22383985 | H27: =H25/G25-1 -> 0.0063197026 | I27: =I25/H25-1 -> 0.081640192 | J27: =J25/I25-1 -> 0.11372951 | K27: =K25/J25-1 -> 0.080956762 | L27: =AVERAGE(H27:K27) -> 0.070661541 | M27: =L27 -> 0.070661541

Sheet IS
B1: McDonald's Corporation (MCD)
B2: $310.45
B5: McDonald's Corporation
B6: MCD 580135101 2550707 NYSE Common stock
B7: Source: FactSet Fundamentals
C8: DEC '15 | D8: DEC '16 | E8: DEC '17 | F8: DEC '18 | G8: DEC '19 | H8: DEC '20 | I8: DEC '21 | J8: DEC '22 | K8: DEC '23 | L8: DEC '24 | M8: SEP '25 | O8: fractin of the year recorded
M9: LTM | O9: calculate with a prop the total of the year
G10: Restate
B11: Sales | C11: 22917 | D11: 22258 | E11: 20232 | F11: 17822 | G11: 19088 | H11: 16849 | I11: 19647 | J11: 22058 | K11: 23581 | L11: 23962 | M11: 23790 | O11: =9/12 -> 0.75
B12: Cost of Goods Sold (COGS) incl. D&A | C12: 14089 | D12: 13033 | E12: 10816 | F12: 8679 | G12: 9134 | H12: 8324 | I12: 9063 | J12: 9611 | K12: 10249 | L12: 10463 | M12: 10171 | O12: =M11/O11 -> 31720
B13: COGS excluding D&A | C13: 12686 | D13: 11662 | E13: 9607 | F13: 7423 | G13: 7689 | H13: 6788 | I13: 7482 | J13: 7831 | K13: 8419 | L13: 8525 | M13: 8200
B14: Depreciation & Amortization Expense | C14: 1403 | D14: 1371 | E14: 1209 | F14: 1256 | G14: 1446 | H14: 1536 | I14: 1580 | J14: 1780 | K14: 1830 | L14: 1939 | M14: 1971
B15: Depreciation | C15: 1297 | D15: 1257 | E15: 1088 | F15: 1104 | G15: 1244 | H15: 1289 | I15: 1295 | J15: 1383 | K15: 1389 | L15: 1387
B16: Amortization of Intangibles | C16: 106 | D16: 114 | E16: 120 | F16: 152 | G16: 202 | H16: 247 | I16: 285 | J16: 396 | K16: 441 | L16: 552
B17: Gross Income | C17: 8828 | D17: 9225 | E17: 9416 | F17: 9143 | G17: 9954 | H17: 8525 | I17: 10585 | J17: 12447 | K17: 13332 | L17: 13499 | M17: 13619
B18: SG&A Expense | C18: 2195 | D18: 2156 | E18: 1978 | F18: 1865 | G18: 2021 | H18: 2243 | I18: 2316 | J18: 2595 | K18: 2492 | L18: 2535 | M18: 2640
B19: Other SG&A | C19: 2195 | D19: 2156 | E19: 1978 | F19: 1865 | G19: 2021 | H19: 2243 | I19: 2316 | J19: 2595 | K19: 2492 | L19: 2535 | M19: 2640
B20: EBIT (Operating Income) | C20: 6632 | D20: 7069 | E20: 7438 | F20: 7278 | G20: 7932 | H20: 6283 | I20: 8269 | J20: 9852 | K20: 10840 | L20: 10964 | M20: 10978
B21: Nonoperating Income - Net | C21: -2 | D21: 218 | E21: 296 | F21: 356 | G21: 267 | H21: -82 | I21: 118 | J21: -1263 | K21: 861 | L21: 272 | M21: 2168
B22: Nonoperating Interest Income | C22: 9 | D22: 4 | E22: 6 | F22: 3 | G22: 33 | H22: 16 | I22: 8 | J22: 42 | K22: 172 | L22: 95 | M22: 73
B23: Equity in Earnings of Affiliates | C23: -132 | D23: 50 | E23: 163 | F23: 128 | G23: 137 | H23: 103 | I23: 149 | J23: 108 | K23: 142 | L23: 145 | M23: 176
B24: Other Income (Expense) | C24: 121 | D24: 165 | E24: 127 | F24: 224 | G24: 97 | H24: -201 | I24: -39 | J24: -1413 | K24: 547 | L24: 31 | M24: 1919
B25: Interest Expense | C25: 575 | D25: 799 | E25: 816 | F25: 831 | G25: 1057 | H25: 1075 | I25: 1010 | J25: 1236 | K25: 1297 | L25: 1435 | M25: 1460
B26: Gross Interest Expense | C26: 584 | D26: 806 | E26: 821 | F26: 835 | G26: 1063 | H26: 1080 | I26: 1016 | J26: 1245 | K26: 1303 | L26: 1443 | M26: 1460
B27: Interest Capitalized | C27: 8 | D27: 6 | E27: 5 | F27: 5 | G27: 7 | H27: 5 | I27: 6 | J27: 9 | K27: 6 | L27: 8
B28: Unusual Expense - Net | C28: 143 | D28: 281 | E28: -684 | F28: 177 | G28: -21 | H28: -261 | I28: -346 | J28: -94 | K28: 671 | L28: 238 | M28: 2015
B29: Restructuring Expense | C29: 212 | D29: 309 | E29: -623 | F29: 196 | G29: 66 | H29: -235 | I29: -241 | J29: 961 | K29: 335 | L29: 268 | M29: 138
B30: Unrealized Valuation Gain/Loss | C30: 69 | D30: 27 | E30: 61 | F30: 19 | G30: 87 | H30: 26 | I30: 104 | J30: 1055 | K30: -336 | L30: 31 | M30: -1878
B31: Hedges/Derivatives | C31: 69 | D31: 27 | E31: 61 | F31: 19 | G31: 87 | H31: 26 | I31: 104 | J31: 1055 | K31: -336 | L31: 31 | M31: -1878
B32: Pretax Income | C32: 5912 | D32: 6207 | E32: 7601 | F32: 6625 | G32: 7164 | H32: 5387 | I32: 7723 | J32: 7446 | K32: 9733 | L32: 9564 | M32: 9671
B33: Income Taxes | C33: 1827 | D33: 1970 | E33: 2998 | F33: 1604 | G33: 1780 | H33: 1237 | I33: 1339 | J33: 1568 | K33: 1899 | L33: 1961 | M33: 2048
B34: Income Taxes - Current Domestic | C34: 1093 | D34: 1056 | E34: 1951 | F34: 404 | G34: 640 | H34: 591 | I34: 944 | J34: 727 | K34: 1482 | L34: 1554
B35: Income Taxes - Current Foreign | C35: 736 | D35: 1401 | E35: 1079 | F35: 1112 | G35: 1006 | H35: 641 | I35: 757 | J35: 1170 | K35: 1052 | L35: 937
B36: Income Taxes - Deferred Domestic | C36: 3 | D36: -98 | E36: -95 | F36: 139 | G36: 52 | H36: 828 | I36: -170 | J36: -120 | K36: -162 | L36: -89
B37: Income Taxes - Deferred Foreign | C37: -4 | D37: -389 | E37: 63 | F37: -52 | G37: 81 | H37: -822 | I37: -192 | J37: -209 | K37: -472 | L37: -442
B38: Consolidated Net Income | C38: 4084 | D38: 4237 | E38: 4603 | F38: 5022 | G38: 5383 | H38: 4150 | I38: 6384 | J38: 5878 | K38: 7833 | L38: 7602 | M38: 7623
B39: Net Income | C39: 4084 | D39: 4237 | E39: 4603 | F39: 5022 | G39: 5383 | H39: 4150 | I39: 6384 | J39: 5878 | K39: 7833 | L39: 7602 | M39: 7623
B40: Net Income available to Common | C40: 4084 | D40: 4237 | E40: 4603 | F40: 5022 | G40: 5383 | H40: 4150 | I40: 6384 | J40: 5878 | K40: 7833 | L40: 7602 | M40: 7623
B41: Per Share
B42: EPS (recurring) | C42: 4.43 | D42: 5.15 | E42: 5.06 | F42: 6.55 | G42: 7.02 | H42: 5.29 | I42: 8.17 | J42: 7.84 | K42: 11.34 | L42: 10.76 | M42: 12.62
...

Sheet BS
B4: McDonald's Corporation
B5: MCD 580135101 2550707 NYSE Common stock
B6: Source: FactSet Fundamentals
C7: DEC '15 | D7: DEC '16 | E7: DEC '17 | F7: DEC '18 | G7: DEC '19 | H7: DEC '20 | I7: DEC '21 | J7: DEC '22 | K7: DEC '23 | L7: DEC '24
G8: Restate
B9: Assets
B10: Cash & Short-Term Investments | C10: 7074.9332 | D10: 1159.8957 | E10: 2051.7988 | F10: 757.55587 | G10: 800.44544 | H10: 2818.9285 | I10: 4141.0482 | J10: 2420.9885 | K10: 4145.4761 | L10: 1047.803
B11: Cash Only | C11: 7074.9332 | D11: 1159.8957 | E11: 2051.7988 | F11: 757.55587 | G11: 800.44544 | H11: 2818.9285 | I11: 4141.0482 | J11: 2420.9885 | K11: 4145.4761 | L11: 1047.803
B12: Short-Term Receivables | C12: 1195.5261 | D12: 1397.5824 | E12: 1645.7362 | F12: 2135.7652 | G12: 1981.4699 | H12: 1724.7354 | I12: 1646.5002 | J12: 1981.7287 | K12: 2252.2972 | L12: 2301.3037
B13: Accounts Receivables, Net | C13: 1195.5261 | D13: 1397.5824 | E13: 1645.7362 | F13: 2135.7652 | G13: 1981.4699 | H13: 1724.7354 | I13: 1646.5002 | J13: 1981.7287 | K13: 2252.2972 | L13: 2301.3037
B14: Accounts Receivables, Gross | C14: 1195.5261 | D14: 1397.5824 | E14: 1645.7362 | F14: 2135.7652 | G14: 1981.4699 | H14: 1724.7354 | I14: 1646.5002 | J14: 1981.7287 | K14: 2252.2972 | L14: 2301.3037
B15: Inventories | C15: 92.147656 | D15: 55.842618 | E15: 48.967356 | F15: 44.701045 | G15: 44.721604 | H15: 41.76372 | I15: 48.892016 | J15: 48.723354 | K15: 47.797947 | L15: 54.080153
B16: Finished Goods | C16: 92.147656 | D16: 55.842618 | E16: 48.967356 | F16: 44.701045 | G16: 44.721604 | H16: 41.76372 | I16: 48.892016 | J16: 48.723354
B17: Other Current Assets | C17: 514.31464 | D17: 1983.598 | E17: 689.87342 | F17: 607.61929 | G17: 342.98441 | H17: 517.10188 | I17: 449.61309 | J17: 630.96744 | K17: 784.23032 | L17: 1037.1801
B18: Miscellaneous Current Assets | C18: 514.31464 | D18: 1983.598 | E18: 689.87342 | F18: 607.61929 | G18: 342.98441 | H18: 517.10188 | I18: 449.61309 | J18: 630.96744 | K18: 784.23032 | L18: 1037.1801
B19: Total Current Assets | C19: 8876.9216 | D19: 4596.9188 | E19: 4436.3758 | F19: 3545.6414 | G19: 3169.6214 | H19: 5102.5295 | I19: 6286.0535 | J19: 5082.408 | K19: 7229.8015 | L19: 4440.3668
B20: Net Property, Plant & Equipment | C20: 21281.046 | D20: 20154.16 | E20: 18694.454 | F20: 19982.242 | G20: 33337.372 | H20: 31699.481 | I20: 33655.118 | J20: 34049.473 | K20: 34782.059 | L20: 37309.511
B21: Property, Plant & Equipment - Gross | C21: 34697.965 | D21: 32655.511 | E21: 30501.666 | F21: 32536.062 | G21: 46603.208 | H21: 45199.788 | I21: 48776.469 | J21: 50225.626 | K21: 51676.46 | L21: 55544.18
B22: Buildings | C22: 24767.191 | D22: 23898.649 | E22: 22723.268 | F22: 24704.544 | G22: 26378.263 | H22: 25812.921 | I22: 28094.707 | J22: 29445.959 | K22: 30219.165 | L22: 32741.67
B23: Land & Improvements | C23: 5139.0039 | D23: 5181.3227 | E23: 4715.3565 | F23: 4829.9873 | G23: 5368.7306 | H23: 5189.081 | I23: 5704.8893 | J23: 6264.98 | K23: 6410.4469 | L23: 7004.3455
B24: Machinery & Equipment | C24: 4288.4102 | D24: 3101.1141 | E24: 2636.3258 | F24: 2574.1153 | G24: 2667.706 | H24: 2549.1398 | I24: 2666.1977 | J24: 2341.1572 | K24: 2437.6047 | L24: 2497.3442
B25: Other Property, Plant & Equipment | C25: 503.36003 | D25: 474.42523 | E25: 426.71553 | F25: 427.41547 | G25: 374.52116 | H25: 347.34992 | I25: 393.68625 | J25: 399.6252 | K25: 375.14146 | L25: 419.12119
B26: Operating Lease Right-of-Use Assets | G26: 11813.987 | H26: 11301.295 | I26: 11916.989 | J26: 11773.905 | K26: 12234.102 | L26: 12881.699
B27: Accumulated Depreciation | C27: 13416.92 | D27: 12501.351 | E27: 11807.212 | F27: 12553.82 | G27: 13265.835 | H27: 13500.307 | I27: 15121.351 | J27: 16176.154 | K27: 16894.401 | L27: 18234.669
B28: Total Long-Term Investments | C28: 863.94181 | D28: 692.20196 | E28: 1043.5543 | F28: 1055.5045 | G28: 1310.4677 | H28: 1089.4528 | I28: 1264.5973 | J28: 1024.3148 | K28: 1150.7718 | L28: 2655.7218
B29: LT Investment - Affiliate Companies | C29: 729.72475 | D29: 688.21997 | E29: 904.14724 | F29: 1052.1804 | G29: 1131.6704 | H29: 1060.1937 | I29: 1056.2786 | J29: 997.42328 | K29: 977.86632 | L29: 2617.0931
B30: Other Long-Term Investments | C30: 134.21707 | D30: 3.981986 | E30: 139.40706 | F30: 3.324148 | G30: 178.79733 | H30: 29.259123 | I30: 208.31868 | J30: 26.891544 | K30: 172.90545 | L30: 38.628681
B31: Intangible Assets | C31: 2316.3951 | D31: 2215.2169 | E31: 1981.7622 | F31: 2039.5398 | G31: 2977.9956 | H31: 2831.3514 | I31: 3145.8847 | J31: 3527.4771 | K31: 3509.1659 | L31: 3913.0854
B32: Goodwill | C32: 2316.3951 | D32: 2215.2169 | E32: 1981.7622 | F32: 2039.5398 | G32: 2385.2116 | H32: 2266.4378 | I32: 2446.7992 | J32: 2717.6388 | K32: 2752.3651 | L32: 3037.18
B33: Other Intangible Assets | C33: 0 | D33: 0 | E33: 0 | F33: 0 | G33: 592.78397 | H33: 564.91357 | I33: 699.08548 | J33: 809.83836 | K33: 756.80082 | L33: 875.90534
B34: Deferred Tax Assets | C34: 490.47224 | D34: 762.26595 | E34: 722.76816 | F34: 1066.7016 | G34: 1014.6103 | H34: 1745.4947 | I34: 2072.6346 | J34: 2320.9182 | K34: 2736.523 | L34: 3421.5354
B35: Other Assets | C35: 1095.9219 | D35: 992.74712 | E35: 1272.0686 | F35: 1012.8155 | G35: 515.81292 | H35: 543.25528 | I35: 932.64159 | J35: 1252.9398 | K35: 1419.3636 | L35: 1549.9758
B36: Tangible Other Assets | C36: 1095.9219 | D36: 992.74712 | E36: 1272.0686 | F36: 1012.8155 | G36: 515.81292 | H36: 543.25528 | I36: 932.64159 | J36: 1252.9398 | K36: 1419.3636 | L36: 1549.9758
B37: Total Assets | C37: 34924.698 | D37: 29413.511 | E37: 28150.983 | F37: 28702.445 | G37: 42325.88 | H37: 43011.565 | I37: 47356.93 | J37: 47257.531 | K37: 50827.685 | L37: 53290.196
B38: Liabilities & Shareholders' Equity
B39: Current
B40: ST Debt & Curr. Portion LT Debt | C40: 0 | D40: 73.192701 | E40: 0 | F40: 0 | G40: 605.87974 | H40: 2407.0124 | I40: 620.38341 | J40: 619.44249 | K40: 2607.6134 | L40: 614.19602
B41: Accounts Payable | C41: 805.21034 | D41: 716.75754 | E41: 770.15324 | F41: 1056.6417 | G41: 880.35636 | H41: 605.86 | I41: 885.33241 | J41: 918.43522 | K41: 998.41582 | L41: 993.72281
B42: Income Tax Payable | C42: 142.50207 | D42: 253.33018 | E42: 221.35243 | F42: 199.71132 | G42: 295.50112 | H42: 605.69654 | I42: 317.18256 | J42: 257.57788 | K42: 638.30174 | L42: 348.62384
B43: Other Current Liabilities | C43: 1768.296 | D43: 2244.987 | E43: 1415.7229 | F43: 1344.7929 | G43: 1444.098 | H43: 1433.2884 | I43: 1712.0999 | J43: 1767.0649 | K43: 1964.8758 | L43: 1772.0907
...
